examples/crypto_events.csv
time,event_type,price,side
0.3988618850708008,market,122452.48,buy
0.3988618850708008,market,122452.48,buy
0.3988618850708008,market,122452.48,buy
0.3988618850708008,market,122452.48,buy
0.3988618850708008,market,122452.48,buy
0.7288618087768555,market,122452.47,sell
0.7288618087768555,market,122452.47,sell
0.7288618087768555,market,122452.47,sell
0.7288618087768555,market,122452.47,sell
0.7288618087768555,market,122452.47,sell
0.7808618545532227,market,122452.48,buy
0.7808618545532227,market,122452.48,buy
0.7808618545532227,market,122452.48,buy
0.7808618545532227,market,122452.48,buy
0.7808618545532227,market,122452.48,buy
0.8288617134094238,market,122452.48,buy
0.8288617134094238,market,122452.48,buy
0.8288617134094238,market,122452.48,buy
0.8288617134094238,market,122452.48,buy
0.8288617134094238,market,122452.48,buy
0.8618617057800293,market,122452.48,buy
0.8618617057800293,market,122452.48,buy
0.8618617057800293,market,122452.48,buy
0.8618617057800293,market,122452.48,buy
0.8618617057800293,market,122452.48,buy
1.0348618030548096,market,122452.48,buy
1.0348618030548096,market,122452.48,buy
1.0348618030548096,market,122452.48,buy
1.0348618030548096,market,122452.48,buy
1.0348618030548096,market,122452.48,buy
1.1048617362976074,market,122452.48,buy
1.1048617362976074,market,122452.48,buy
1.1048617362976074,market,122452.48,buy
1.1048617362976074,market,122452.48,buy
1.1048617362976074,market,122452.48,buy
1.2688617706298828,market,122452.48,buy
1.2688617706298828,market,122452.48,buy
1.2688617706298828,market,122452.48,buy
1.2688617706298828,market,122452.48,buy
1.2688617706298828,market,122452.48,buy
1.3118617534637451,market,122452.47,sell
1.3118617534637451,market,122452.47,sell
1.3118617534637451,market,122452.47,sell
1.3118617534637451,market,122452.47,sell
1.3118617534637451,market,122452.47,sell
1.3948616981506348,market,122452.47,sell
1.3948616981506348,market,122452.47,sell
1.3948616981506348,market,122452.47,sell
1.3948616981506348,market,122452.47,sell
1.3948616981506348,market,122452.47,sell
2.1108617782592773,market,122452.48,buy
2.1108617782592773,market,122452.48,buy
2.1108617782592773,market,122452.48,buy
2.1108617782592773,market,122452.48,buy
2.1108617782592773,market,122452.48,buy
2.384861707687378,market,122452.47,sell
2.384861707687378,market,122452.47,sell
2.384861707687378,market,122452.47,sell
2.384861707687378,market,122452.47,sell
2.384861707687378,market,122452.47,sell
2.3968617916107178,market,122452.47,sell
2.3968617916107178,market,122452.47,sell
2.3968617916107178,market,122452.47,sell
2.3968617916107178,market,122452.47,sell
2.3968617916107178,market,122452.47,sell
3.190861701965332,market,122452.47,sell
3.190861701965332,market,122452.47,sell
3.190861701965332,market,122452.47,sell
3.190861701965332,market,122452.47,sell
3.191861867904663,market,122452.48,buy
3.191861867904663,market,122452.48,buy
3.191861867904663,market,122452.48,buy
3.191861867904663,market,122452.48,buy
3.319861888885498,market,122452.47,sell
3.319861888885498,market,122452.47,sell
3.319861888885498,market,122452.47,sell
3.319861888885498,market,122452.47,sell
4.479861736297607,market,122452.48,buy
4.479861736297607,market,122452.48,buy
4.479861736297607,market,122452.48,buy
4.479861736297607,market,122452.48,buy
4.525861740112305,market,122452.47,sell
4.525861740112305,market,122452.47,sell
4.525861740112305,market,122452.47,sell
4.525861740112305,market,122452.47,sell
4.703861713409424,market,122452.47,sell
4.703861713409424,market,122452.47,sell
4.703861713409424,market,122452.47,sell
4.703861713409424,market,122452.47,sell
4.950861692428589,market,122452.48,buy
4.950861692428589,market,122452.48,buy
4.950861692428589,market,122452.48,buy
4.950861692428589,market,122452.48,buy
4.950861692428589,market,122452.48,buy
5.229861736297607,market,122452.47,sell
5.229861736297607,market,122452.47,sell
5.229861736297607,market,122452.47,sell
5.229861736297607,market,122452.47,sell
5.229861736297607,market,122452.47,sell
5.296861886978149,market,122452.48,buy
5.296861886978149,market,122452.48,buy
5.296861886978149,market,122452.48,buy
5.296861886978149,market,122452.48,buy
5.296861886978149,market,122452.48,buy
5.30886173248291,market,122452.47,sell
5.30886173248291,market,122452.47,sell
5.30886173248291,market,122452.47,sell
5.30886173248291,market,122452.47,sell
5.30886173248291,market,122452.47,sell
5.515861749649048,market,122452.47,sell
5.515861749649048,market,122452.47,sell
5.515861749649048,market,122452.47,sell
5.515861749649048,market,122452.47,sell
5.515861749649048,market,122452.47,sell
5.86286187171936,market,122452.48,buy
5.86286187171936,market,122452.48,buy
5.86286187171936,market,122452.48,buy
5.86286187171936,market,122452.48,buy
5.86286187171936,market,122452.48,buy
5.926861763000488,market,122452.48,buy
5.926861763000488,market,122452.48,buy
5.926861763000488,market,122452.48,buy
5.926861763000488,market,122452.48,buy
5.926861763000488,market,122452.48,buy
5.978161811828613,limit,122500.78125936813,buy
5.978161811828613,limit,122390.81797704725,sell
6.309861898422241,market,122452.47,sell
6.309861898422241,market,122452.47,sell
6.309861898422241,market,122452.47,sell
6.309861898422241,market,122452.47,sell
6.341861724853516,market,122452.47,sell
6.341861724853516,market,122452.47,sell
6.341861724853516,market,122452.47,sell
6.341861724853516,market,122452.47,sell
6.4748618602752686,market,122452.47,sell
6.4748618602752686,market,122452.47,sell
6.4748618602752686,market,122452.47,sell
6.4748618602752686,market,122452.47,sell
6.596861839294434,market,122452.48,buy
6.596861839294434,market,122452.48,buy
6.596861839294434,market,122452.48,buy
6.596861839294434,market,122452.48,buy
6.819861888885498,market,122452.47,sell
6.819861888885498,market,122452.47,sell
6.819861888885498,market,122452.47,sell
6.819861888885498,market,122452.47,sell
7.029861688613892,market,122452.47,sell
7.029861688613892,market,122452.47,sell
7.029861688613892,market,122452.47,sell
7.029861688613892,market,122452.47,sell
7.079861879348755,market,122452.48,buy
7.079861879348755,market,122452.48,buy
7.079861879348755,market,122452.48,buy
7.079861879348755,market,122452.48,buy
7.4768617153167725,market,122452.48,buy
7.4768617153167725,market,122452.48,buy
7.4768617153167725,market,122452.48,buy
7.4768617153167725,market,122452.48,buy
7.4768617153167725,market,122452.48,buy
7.617861747741699,market,122452.47,sell
7.617861747741699,market,122452.47,sell
7.617861747741699,market,122452.47,sell
7.617861747741699,market,122452.47,sell
7.617861747741699,market,122452.47,sell
8.279861688613892,market,122452.47,sell
8.279861688613892,market,122452.47,sell
8.279861688613892,market,122452.47,sell
8.279861688613892,market,122452.47,sell
8.279861688613892,market,122452.47,sell
8.516861915588379,market,122452.47,sell
8.516861915588379,market,122452.47,sell
8.516861915588379,market,122452.47,sell
8.516861915588379,market,122452.47,sell
8.516861915588379,market,122452.47,sell
8.816861867904663,market,122452.47,sell
8.816861867904663,market,122452.47,sell
8.816861867904663,market,122452.47,sell
8.816861867904663,market,122452.47,sell
8.816861867904663,market,122452.47,sell
9.318701028823853,limit,122338.81343170449,buy
9.318701028823853,cancel,122452.47,buy
9.351861715316772,market,122452.47,sell
9.351861715316772,market,122452.47,sell
9.351861715316772,market,122452.47,sell
9.351861715316772,market,122452.47,sell
9.351861715316772,market,122452.47,sell
9.574861764907837,market,122452.47,sell
9.574861764907837,market,122452.47,sell
9.574861764907837,market,122452.47,sell
9.574861764907837,market,122452.47,sell
9.688861846923828,market,122452.48,buy
9.688861846923828,market,122452.48,buy
9.688861846923828,market,122452.48,buy
9.688861846923828,market,122452.48,buy
9.781861782073975,market,122452.47,sell
9.781861782073975,market,122452.47,sell
9.781861782073975,market,122452.47,sell
9.781861782073975,market,122452.47,sell
9.833861827850342,market,122452.47,sell
9.833861827850342,market,122452.47,sell
